Traceback (most recent call last):
  File "c:\Users\aves\.conda\envs\lira_db\lib\site-packages\IPython\core\interactiveshell.py", line 3397, in run_code
    exec(code_obj, self.user_global_ns, self.user_ns)
  File "<ipython-input-1-946c15c1b2b3>", line 151, in <cell line: 106>
    [MSE_cv_linear_epoch, MSE_cv_dB_epoch, MSE_train_linear_epoch, MSE_train_dB_epoch] = RTSNet_Pipeline.NNTrain(sys_model, cv_input, cv_target, train_input, train_target, path_results)
  File "c:\Users\aves\Documents\RTSNet_constrained\Pipeline_ERTS.py", line 132, in NNTrain
    x_out_training_forward[:, t] = self.model(y_training[:, t], None, None, None)
  File "c:\Users\aves\.conda\envs\lira_db\lib\site-packages\torch\nn\modules\module.py", line 1110, in _call_impl
    return forward_call(*input, **kwargs)
  File "c:\Users\aves\Documents\RTSNet_constrained\RTSNet_nn.py", line 222, in forward
    return self.KNet_step(yt)
  File "c:\Users\aves\Documents\RTSNet_constrained\KalmanNet_nn.py", line 215, in KNet_step
    self.step_KGain_est(y)
  File "c:\Users\aves\Documents\RTSNet_constrained\KalmanNet_nn.py", line 201, in step_KGain_est
    KG = self.KGain_step(obs_diff, obs_innov_diff, fw_evol_diff, fw_update_diff)
  File "c:\Users\aves\Documents\RTSNet_constrained\KalmanNet_nn.py", line 282, in KGain_step
    out_FC1 = self.FC1(in_FC1)
  File "c:\Users\aves\.conda\envs\lira_db\lib\site-packages\torch\nn\modules\module.py", line 1110, in _call_impl
    return forward_call(*input, **kwargs)
  File "c:\Users\aves\.conda\envs\lira_db\lib\site-packages\torch\nn\modules\container.py", line 141, in forward
    input = module(input)
  File "c:\Users\aves\.conda\envs\lira_db\lib\site-packages\torch\nn\modules\module.py", line 1110, in _call_impl
    return forward_call(*input, **kwargs)
  File "c:\Users\aves\.conda\envs\lira_db\lib\site-packages\torch\nn\modules\activation.py", line 98, in forward
    return F.relu(input, inplace=self.inplace)
  File "c:\Users\aves\.conda\envs\lira_db\lib\site-packages\torch\nn\functional.py", line 1442, in relu
    result = torch.relu(input)
RuntimeError: bad allocation
During handling of the above exception, another exception occurred:
Traceback (most recent call last):
  File "c:\Users\aves\.conda\envs\lira_db\lib\site-packages\executing\executing.py", line 317, in executing
    args = executing_cache[key]
KeyError: (<code object run_code at 0x000001C065DE9450, file "c:\Users\aves\.conda\envs\lira_db\lib\site-packages\IPython\core\interactiveshell.py", line 3361>, 1925854434384, 74)
During handling of the above exception, another exception occurred:
Traceback (most recent call last):
  File "c:\Users\aves\.conda\envs\lira_db\lib\site-packages\IPython\core\interactiveshell.py", line 1992, in showtraceback
    stb = self.InteractiveTB.structured_traceback(
  File "c:\Users\aves\.conda\envs\lira_db\lib\site-packages\IPython\core\ultratb.py", line 1118, in structured_traceback
    return FormattedTB.structured_traceback(
  File "c:\Users\aves\.conda\envs\lira_db\lib\site-packages\IPython\core\ultratb.py", line 1012, in structured_traceback
    return VerboseTB.structured_traceback(
  File "c:\Users\aves\.conda\envs\lira_db\lib\site-packages\IPython\core\ultratb.py", line 865, in structured_traceback
    formatted_exception = self.format_exception_as_a_whole(etype, evalue, etb, number_of_lines_of_context,
  File "c:\Users\aves\.conda\envs\lira_db\lib\site-packages\IPython\core\ultratb.py", line 799, in format_exception_as_a_whole
    self.get_records(etb, number_of_lines_of_context, tb_offset) if etb else []
  File "c:\Users\aves\.conda\envs\lira_db\lib\site-packages\IPython\core\ultratb.py", line 854, in get_records
    return list(stack_data.FrameInfo.stack_data(etb, options=options))[tb_offset:]
  File "c:\Users\aves\.conda\envs\lira_db\lib\site-packages\stack_data\core.py", line 565, in stack_data
    yield from collapse_repeated(
  File "c:\Users\aves\.conda\envs\lira_db\lib\site-packages\stack_data\utils.py", line 84, in collapse_repeated
    yield from map(mapper, original_group)
  File "c:\Users\aves\.conda\envs\lira_db\lib\site-packages\stack_data\core.py", line 555, in mapper
    return cls(f, options)
  File "c:\Users\aves\.conda\envs\lira_db\lib\site-packages\stack_data\core.py", line 520, in __init__
    self.executing = Source.executing(frame_or_tb)
  File "c:\Users\aves\.conda\envs\lira_db\lib\site-packages\executing\executing.py", line 369, in executing
    args = find(source=cls.for_frame(frame), retry_cache=True)
  File "c:\Users\aves\.conda\envs\lira_db\lib\site-packages\executing\executing.py", line 252, in for_frame
    return cls.for_filename(frame.f_code.co_filename, frame.f_globals or {}, use_cache)
  File "c:\Users\aves\.conda\envs\lira_db\lib\site-packages\executing\executing.py", line 270, in for_filename
    result = source_cache[filename] = cls._for_filename_and_lines(filename, lines)
  File "c:\Users\aves\.conda\envs\lira_db\lib\site-packages\executing\executing.py", line 281, in _for_filename_and_lines
    result = source_cache[(filename, lines)] = cls(filename, lines)
  File "c:\Users\aves\.conda\envs\lira_db\lib\site-packages\stack_data\core.py", line 79, in __init__
    super(Source, self).__init__(*args, **kwargs)
  File "c:\Users\aves\.conda\envs\lira_db\lib\site-packages\executing\executing.py", line 228, in __init__
    self.tree = ast.parse(ast_text, filename=filename)
  File "c:\Users\aves\.conda\envs\lira_db\lib\ast.py", line 50, in parse
    return compile(source, filename, mode, flags,
SystemError: <built-in function compile> returned NULL without setting an error
